[2023-09-14T14:38:50.368+0000] {taskinstance.py:1125} INFO - Dependencies all met for dep_context=non-requeueable deps ti=<TaskInstance: keren.narasio manual__2023-09-14T14:38:27.377639+00:00 [queued]>
[2023-09-14T14:38:50.444+0000] {taskinstance.py:1125} INFO - Dependencies all met for dep_context=requeueable deps ti=<TaskInstance: keren.narasio manual__2023-09-14T14:38:27.377639+00:00 [queued]>
[2023-09-14T14:38:50.445+0000] {taskinstance.py:1331} INFO - Starting attempt 1 of 4
[2023-09-14T14:38:50.516+0000] {taskinstance.py:1350} INFO - Executing <Task(PythonOperator): narasio> on 2023-09-14 14:38:27.377639+00:00
[2023-09-14T14:38:50.552+0000] {standard_task_runner.py:57} INFO - Started process 2694 to run task
[2023-09-14T14:38:50.596+0000] {standard_task_runner.py:84} INFO - Running: ['***', 'tasks', 'run', 'keren', 'narasio', 'manual__2023-09-14T14:38:27.377639+00:00', '--job-id', '3', '--raw', '--subdir', 'DAGS_FOLDER/test.py', '--cfg-path', '/tmp/tmpjvgjn7ls']
[2023-09-14T14:38:50.610+0000] {standard_task_runner.py:85} INFO - Job 3: Subtask narasio
[2023-09-14T14:38:50.798+0000] {task_command.py:410} INFO - Running <TaskInstance: keren.narasio manual__2023-09-14T14:38:27.377639+00:00 [running]> on host c525017cb5db
[2023-09-14T14:38:51.244+0000] {taskinstance.py:1570} INFO - Exporting env vars: AIRFLOW_CTX_DAG_OWNER='agung_keren' AIRFLOW_CTX_DAG_ID='keren' AIRFLOW_CTX_TASK_ID='narasio' AIRFLOW_CTX_EXECUTION_DATE='2023-09-14T14:38:27.377639+00:00' AIRFLOW_CTX_TRY_NUMBER='1' AIRFLOW_CTX_DAG_RUN_ID='manual__2023-09-14T14:38:27.377639+00:00'
[2023-09-14T14:38:51.260+0000] {taskinstance.py:1847} ERROR - Task failed with exception
Traceback (most recent call last):
  File "/home/airflow/.local/lib/python3.7/site-packages/airflow/operators/python.py", line 181, in execute
    return_value = self.execute_callable()
  File "/home/airflow/.local/lib/python3.7/site-packages/airflow/operators/python.py", line 198, in execute_callable
    return self.python_callable(*self.op_args, **self.op_kwargs)
  File "/opt/airflow/dags/test.py", line 15, in ingest
    port='5432'
  File "/home/airflow/.local/lib/python3.7/site-packages/psycopg2/__init__.py", line 122, in connect
    conn = _connect(dsn, connection_factory=connection_factory, **kwasync)
psycopg2.OperationalError: connection to server at "localhost" (127.0.0.1), port 5432 failed: Connection refused
	Is the server running on that host and accepting TCP/IP connections?
connection to server at "localhost" (::1), port 5432 failed: Cannot assign requested address
	Is the server running on that host and accepting TCP/IP connections?

[2023-09-14T14:38:51.371+0000] {taskinstance.py:1373} INFO - Marking task as UP_FOR_RETRY. dag_id=keren, task_id=narasio, execution_date=20230914T143827, start_date=20230914T143850, end_date=20230914T143851
[2023-09-14T14:38:51.489+0000] {standard_task_runner.py:109} ERROR - Failed to execute job 3 for task narasio (connection to server at "localhost" (127.0.0.1), port 5432 failed: Connection refused
	Is the server running on that host and accepting TCP/IP connections?
connection to server at "localhost" (::1), port 5432 failed: Cannot assign requested address
	Is the server running on that host and accepting TCP/IP connections?
; 2694)
[2023-09-14T14:38:51.528+0000] {local_task_job_runner.py:232} INFO - Task exited with return code 1
[2023-09-14T14:38:51.601+0000] {taskinstance.py:2674} INFO - 0 downstream tasks scheduled from follow-on schedule check
